{
  "id": "CVE-2025-46149",
  "sourceIdentifier": "cve@mitre.org",
  "published": "2025-09-25T15:16:12.153",
  "lastModified": "2025-09-25T15:16:12.153",
  "vulnStatus": "Received",
  "descriptions": [
    {
      "lang": "en",
      "value": "In PyTorch before 2.7.0, when inductor is used, nn.Fold has an assertion error."
    }
  ],
  "metrics": {},
  "references": [
    {
      "url": "https://gist.github.com/shaoyuyoung/4bcefba4004f8271e64b5185c95a248a",
      "source": "cve@mitre.org"
    },
    {
      "url": "https://github.com/pytorch/pytorch/issues/147848",
      "source": "cve@mitre.org"
    },
    {
      "url": "https://github.com/pytorch/pytorch/pull/147961",
      "source": "cve@mitre.org"
    }
  ]
}